Workbook
Name Sel_Month: Dashboard!$D$2
Name Unique_Months: OFFSET(Conf!$D$1, 0, 0, COUNTA(Conf!$D:$D), 1)

Sheet Dashboard
A1: Spending Report | G1: Budgets | L1: Custom Categories
C2: Month | D2: 45413 | G2: Custom Category | H2: Frequency | I2: Amount | J2: Monthly | L2: Name | M2: Amount | N2: Custom Category
G3: Home Insurance | H3: Monthly | I3: 428 | J3: =Budgets[[#This Row],[Amount]]*_xlfn.XLOOKUP(Budgets[[#This Row],[Frequency]],Frequency[Frequency],Frequency[Factor],1,0) -> 428 | L3: BELAIR INS/ASS | M3: <100 | N3: Insurance,Home
A4: Row Labels | B4: 6M Average | C4: Budget | D4: Montly Spending | E4: Used | G4: Food and Drink, Restaurants | H4: Weekly | I4: 200 | J4: =Budgets[[#This Row],[Amount]]*_xlfn.XLOOKUP(Budgets[[#This Row],[Frequency]],Frequency[Frequency],Frequency[Factor],1,0) -> 800 | L4: BELAIR INS/ASS | M4: >100 | N4: Insurance,Car
A5: Bank Fees | B5: 2.5077778 | C5: 2.5077778 | D5: {=_xlfn.IFS(A5="","",A5="Grand Total",SUM(D$4:D4),TRUE,IF(COUNTIF(Transactions[Custom Category],Dashboard!A5)>0,SUMIFS(Transactions[Amount],Transactions[Custom Category],Dashboard!A5,Transactions[Month],Sel_Month),SUMIFS(Transactions[Amount],Transactions[Name],Dashboard!A5,Transactions[Month],Sel_Month)))} -> 5.1 | E5: =IF(C5="","",IF(C5=0,0,1-((C5-D5)/C5))) -> 2.033673 | L5: NEW YORK TIMES | N5: Subscriptions
A6: Business,Advertising | B6: 6.21 | C6: 6.21 | D6: {=_xlfn.IFS(A6="","",A6="Grand Total",SUM(D$4:D5),TRUE,IF(COUNTIF(Transactions[Custom Category],Dashboard!A6)>0,SUMIFS(Transactions[Amount],Transactions[Custom Category],Dashboard!A6,Transactions[Month],Sel_Month),SUMIFS(Transactions[Amount],Transactions[Name],Dashboard!A6,Transactions[Month],Sel_Month)))} -> 12.42 | E6: =IF(C6="","",IF(C6=0,0,1-((C6-D6)/C6))) -> 2 | L6: McDonald | N6: Food and Drink, Restaurants
A7: Discretionary | B7: 16.39 | C7: 16.39 | D7: {=_xlfn.IFS(A7="","",A7="Grand Total",SUM(D$4:D6),TRUE,IF(COUNTIF(Transactions[Custom Category],Dashboard!A7)>0,SUMIFS(Transactions[Amount],Transactions[Custom Category],Dashboard!A7,Transactions[Month],Sel_Month),SUMIFS(Transactions[Amount],Transactions[Name],Dashboard!A7,Transactions[Month],Sel_Month)))} -> 0 | E7: =IF(C7="","",IF(C7=0,0,1-((C7-D7)/C7))) -> 0 | L7: e-Transfer sent Manuel | N7: Transfer,Internal
A8: Food and Drink, Restaurants | B8: 414.67286 | C8: 800 | D8: {=_xlfn.IFS(A8="","",A8="Grand Total",SUM(D$4:D7),TRUE,IF(COUNTIF(Transactions[Custom Category],Dashboard!A8)>0,SUMIFS(Transactions[Amount],Transactions[Custom Category],Dashboard!A8,Transactions[Month],Sel_Month),SUMIFS(Transactions[Amount],Transactions[Name],Dashboard!A8,Transactions[Month],Sel_Month)))} -> 0 | E8: =IF(C8="","",IF(C8=0,0,1-((C8-D8)/C8))) -> 0 | L8: e-Transfer sent Paula | N8: Transfer,Internal
A9: Groceries | B9: 248.36 | C9: 248.36 | D9: {=_xlfn.IFS(A9="","",A9="Grand Total",SUM(D$4:D8),TRUE,IF(COUNTIF(Transactions[Custom Category],Dashboard!A9)>0,SUMIFS(Transactions[Amount],Transactions[Custom Category],Dashboard!A9,Transactions[Month],Sel_Month),SUMIFS(Transactions[Amount],Transactions[Name],Dashboard!A9,Transactions[Month],Sel_Month)))} -> 0 | E9: =IF(C9="","",IF(C9=0,0,1-((C9-D9)/C9))) -> 0 | L9: Subscription | N9: Subscriptions
A10: Home,Supplies | B10: 128.65625 | C10: 128.65625 | D10: {=_xlfn.IFS(A10="","",A10="Grand Total",SUM(D$4:D9),TRUE,IF(COUNTIF(Transactions[Custom Category],Dashboard!A10)>0,SUMIFS(Transactions[Amount],Transactions[Custom Category],Dashboard!A10,Transactions[Month],Sel_Month),SUMIFS(Transactions[Amount],Transactions[Name],Dashboard!A10,Transactions[Month],Sel_Month)))} -> 98.41 | E10: =IF(C10="","",IF(C10=0,0,1-((C10-D10)/C10))) -> 0.76490649 | L10: SPL | N10: Loans,Car
A11: Income,Interest | B11: -0.01 | C11: -0.01 | D11: {=_xlfn.IFS(A11="","",A11="Grand Total",SUM(D$4:D10),TRUE,IF(COUNTIF(Transactions[Custom Category],Dashboard!A11)>0,SUMIFS(Transactions[Amount],Transactions[Custom Category],Dashboard!A11,Transactions[Month],Sel_Month),SUMIFS(Transactions[Amount],Transactions[Name],Dashboard!A11,Transactions[Month],Sel_Month)))} -> 0 | E11: =IF(C11="","",IF(C11=0,0,1-((C11-D11)/C11))) -> 0 | L11: Service, Utilities, Electric | N11: Utilities,Electric
A12: Income,Repayment | B12: -3209.0714 | C12: -3209.0714 | D12: {=_xlfn.IFS(A12="","",A12="Grand Total",SUM(D$4:D11),TRUE,IF(COUNTIF(Transactions[Custom Category],Dashboard!A12)>0,SUMIFS(Transactions[Amount],Transactions[Custom Category],Dashboard!A12,Transactions[Month],Sel_Month),SUMIFS(Transactions[Amount],Transactions[Name],Dashboard!A12,Transactions[Month],Sel_Month)))} -> -3266 | E12: =IF(C12="","",IF(C12=0,0,1-((C12-D12)/C12))) -> 1.0177399 | L12: Online Banking foreign exchange | N12: Income,Salary
A13: Income,Salary | B13: -18125.097 | C13: -18125.097 | D13: {=_xlfn.IFS(A13="","",A13="Grand Total",SUM(D$4:D12),TRUE,IF(COUNTIF(Transactions[Custom Category],Dashboard!A13)>0,SUMIFS(Transactions[Amount],Transactions[Custom Category],Dashboard!A13,Transactions[Month],Sel_Month),SUMIFS(Transactions[Amount],Transactions[Name],Dashboard!A13,Transactions[Month],Sel_Month)))} -> -22459.99 | E13: =IF(C13="","",IF(C13=0,0,1-((C13-D13)/C13))) -> 1.2391652 | L13: Bank Fees, Overdraft | N13: Bank Fees
A14: Income,Tax Refund | B14: -3713.1 | C14: -3713.1 | D14: {=_xlfn.IFS(A14="","",A14="Grand Total",SUM(D$4:D13),TRUE,IF(COUNTIF(Transactions[Custom Category],Dashboard!A14)>0,SUMIFS(Transactions[Amount],Transactions[Custom Category],Dashboard!A14,Transactions[Month],Sel_Month),SUMIFS(Transactions[Amount],Transactions[Name],Dashboard!A14,Transactions[Month],Sel_Month)))} -> -3713.1 | E14: =IF(C14="","",IF(C14=0,0,1-((C14-D14)/C14))) -> 1 | L14: CITY OF TORONTO | N14: Utilities,Water
A15: Insurance,Car | B15: 432.996 | C15: 432.996 | D15: {=_xlfn.IFS(A15="","",A15="Grand Total",SUM(D$4:D14),TRUE,IF(COUNTIF(Transactions[Custom Category],Dashboard!A15)>0,SUMIFS(Transactions[Amount],Transactions[Custom Category],Dashboard!A15,Transactions[Month],Sel_Month),SUMIFS(Transactions[Amount],Transactions[Name],Dashboard!A15,Transactions[Month],Sel_Month)))} -> 438.75 | E15: =IF(C15="","",IF(C15=0,0,1-((C15-D15)/C15))) -> 1.0132888 | L15: Interest, Interest Earned | N15: Income,Interest
A16: Insurance,Home | B16: 57.905 | C16: 57.905 | D16: {=_xlfn.IFS(A16="","",A16="Grand Total",SUM(D$4:D15),TRUE,IF(COUNTIF(Transactions[Custom Category],Dashboard!A16)>0,SUMIFS(Transactions[Amount],Transactions[Custom Category],Dashboard!A16,Transactions[Month],Sel_Month),SUMIFS(Transactions[Amount],Transactions[Name],Dashboard!A16,Transactions[Month],Sel_Month)))} -> 56.05 | E16: =IF(C16="","",IF(C16=0,0,1-((C16-D16)/C16))) -> 0.96796477 | L16: Payment | N16: Transfer,Internal
... A29: Utilities,Electric | B29: 139.88333 | C29: 139.88333 | D29: {=_xlfn.IFS(A29="","",A29="Grand Total",SUM(D$4:D28),TRUE,IF(COUNTIF(Transactions[Custom Category],Dashboard!A29)>0,SUMIFS(Transactions[Amount],Transactions[Custom Category],Dashboard!A29,Transactions[Month],Sel_Month),SUMIFS(Transactions[Amount],Transactions[Name],Dashboard!A29,Transactions[Month],Sel_Month)))} -> 153.32 | E29: =IF(C29="","",IF(C29=0,0,1-((C29-D29)/C29))) -> 1.0960562 | L29: Autodeposit PAULA ANDREA AMARILES | N29: Transfer,Internal
A30: Utilities,Gas | B30: 153.08333 | C30: 153.08333 | D30: {=_xlfn.IFS(A30="","",A30="Grand Total",SUM(D$4:D29),TRUE,IF(COUNTIF(Transactions[Custom Category],Dashboard!A30)>0,SUMIFS(Transactions[Amount],Transactions[Custom Category],Dashboard!A30,Transactions[Month],Sel_Month),SUMIFS(Transactions[Amount],Transactions[Name],Dashboard!A30,Transactions[Month],Sel_Month)))} -> 153.29 | E30: =IF(C30="","",IF(C30=0,0,1-((C30-D30)/C30))) -> 1.00135 | L30: Lorena | M30: <0 | N30: Income,Repayment
A31: Utilities,Water | B31: 489.91 | C31: 489.91 | D31: {=_xlfn.IFS(A31="","",A31="Grand Total",SUM(D$4:D30),TRUE,IF(COUNTIF(Transactions[Custom Category],Dashboard!A31)>0,SUMIFS(Transactions[Amount],Transactions[Custom Category],Dashboard!A31,Transactions[Month],Sel_Month),SUMIFS(Transactions[Amount],Transactions[Name],Dashboard!A31,Transactions[Month],Sel_Month)))} -> 0 | E31: =IF(C31="","",IF(C31=0,0,1-((C31-D31)/C31))) -> 0 | L31: David Alexander | M31: <0 | N31: Income,Repayment
A32: Total | B32: 14532.99 | C32: 14532.99 | D32: {=_xlfn.IFS(A32="","",A32="Grand Total",SUM(D$4:D31),TRUE,IF(COUNTIF(Transactions[Custom Category],Dashboard!A32)>0,SUMIFS(Transactions[Amount],Transactions[Custom Category],Dashboard!A32,Transactions[Month],Sel_Month),SUMIFS(Transactions[Amount],Transactions[Name],Dashboard!A32,Transactions[Month],Sel_Month)))} -> 0 | E32: =IF(C32="","",IF(C32=0,0,1-((C32-D32)/C32))) -> 0 | L32: Ana Maria | M32: <0 | N32: Income,Repayment
D33: {=_xlfn.IFS(A33="","",A33="Grand Total",SUM(D$4:D32),TRUE,IF(COUNTIF(Transactions[Custom Category],Dashboard!A33)>0,SUMIFS(Transactions[Amount],Transactions[Custom Category],Dashboard!A33,Transactions[Month],Sel_Month),SUMIFS(Transactions[Amount],Transactions[Name],Dashboard!A33,Transactions[Month],Sel_Month)))} | E33: =IF(C33="","",IF(C33=0,0,1-((C33-D33)/C33))) | L33: Barian | M33: <0 | N33: Income,Repayment
D34: {=_xlfn.IFS(A34="","",A34="Grand Total",SUM(D$4:D33),TRUE,IF(COUNTIF(Transactions[Custom Category],Dashboard!A34)>0,SUMIFS(Transactions[Amount],Transactions[Custom Category],Dashboard!A34,Transactions[Month],Sel_Month),SUMIFS(Transactions[Amount],Transactions[Name],Dashboard!A34,Transactions[Month],Sel_Month)))} | E34: =IF(C34="","",IF(C34=0,0,1-((C34-D34)/C34))) | L34: Bridgeway | N34: Rent
D35: {=_xlfn.IFS(A35="","",A35="Grand Total",SUM(D$4:D34),TRUE,IF(COUNTIF(Transactions[Custom Category],Dashboard!A35)>0,SUMIFS(Transactions[Amount],Transactions[Custom Category],Dashboard!A35,Transactions[Month],Sel_Month),SUMIFS(Transactions[Amount],Transactions[Name],Dashboard!A35,Transactions[Month],Sel_Month)))} | E35: =IF(C35="","",IF(C35=0,0,1-((C35-D35)/C35)))
D36: {=_xlfn.IFS(A36="","",A36="Total",SUM(D$4:D35),TRUE,IF(COUNTIF(Transactions[Custom Category],Dashboard!A36)>0,SUMIFS(Transactions[Amount],Transactions[Custom Category],Dashboard!A36,Transactions[Month],Sel_Month),SUMIFS(Transactions[Amount],Transactions[Name],Dashboard!A36,Transactions[Month],Sel_Month)))} | E36: =IF(C36="","",IF(C36=0,0,1-((C36-D36)/C36)))
D37: {=_xlfn.IFS(A37="","",A37="Grand Total",SUM(D$4:D36),TRUE,IF(COUNTIF(Transactions[Custom Category],Dashboard!A37)>0,SUMIFS(Transactions[Amount],Transactions[Custom Category],Dashboard!A37,Transactions[Month],Sel_Month),SUMIFS(Transactions[Amount],Transactions[Name],Dashboard!A37,Transactions[Month],Sel_Month)))} | E37: =IF(C37="","",IF(C37=0,0,1-((C37-D37)/C37)))
D38: {=_xlfn.IFS(A38="","",A38="Grand Total",SUM(D$4:D37),TRUE,IF(COUNTIF(Transactions[Custom Category],Dashboard!A38)>0,SUMIFS(Transactions[Amount],Transactions[Custom Category],Dashboard!A38,Transactions[Month],Sel_Month),SUMIFS(Transactions[Amount],Transactions[Name],Dashboard!A38,Transactions[Month],Sel_Month)))} | E38: =IF(C38="","",IF(C38=0,0,1-((C38-D38)/C38)))
D39: {=_xlfn.IFS(A39="","",A39="Grand Total",SUM(D$4:D38),TRUE,IF(COUNTIF(Transactions[Custom Category],Dashboard!A39)>0,SUMIFS(Transactions[Amount],Transactions[Custom Category],Dashboard!A39,Transactions[Month],Sel_Month),SUMIFS(Transactions[Amount],Transactions[Name],Dashboard!A39,Transactions[Month],Sel_Month)))} | E39: =IF(C39="","",IF(C39=0,0,1-((C39-D39)/C39)))
D40: {=_xlfn.IFS(A40="","",A40="Grand Total",SUM(D$4:D39),TRUE,IF(COUNTIF(Transactions[Custom Category],Dashboard!A40)>0,SUMIFS(Transactions[Amount],Transactions[Custom Category],Dashboard!A40,Transactions[Month],Sel_Month),SUMIFS(Transactions[Amount],Transactions[Name],Dashboard!A40,Transactions[Month],Sel_Month)))} | E40: =IF(C40="","",IF(C40=0,0,1-((C40-D40)/C40)))
D41: {=_xlfn.IFS(A41="","",A41="Grand Total",SUM(D$4:D40),TRUE,IF(COUNTIF(Transactions[Custom Category],Dashboard!A41)>0,SUMIFS(Transactions[Amount],Transactions[Custom Category],Dashboard!A41,Transactions[Month],Sel_Month),SUMIFS(Transactions[Amount],Transactions[Name],Dashboard!A41,Transactions[Month],Sel_Month)))} | E41: =IF(C41="","",IF(C41=0,0,1-((C41-D41)/C41)))
D42: {=_xlfn.IFS(A42="","",A42="Grand Total",SUM(D$4:D41),TRUE,IF(COUNTIF(Transactions[Custom Category],Dashboard!A42)>0,SUMIFS(Transactions[Amount],Transactions[Custom Category],Dashboard!A42,Transactions[Month],Sel_Month),SUMIFS(Transactions[Amount],Transactions[Name],Dashboard!A42,Transactions[Month],Sel_Month)))} | E42: =IF(C42="","",IF(C42=0,0,1-((C42-D42)/C42)))
D43: {=_xlfn.IFS(A43="","",A43="Grand Total",SUM(D$4:D42),TRUE,IF(COUNTIF(Transactions[Custom Category],Dashboard!A43)>0,SUMIFS(Transactions[Amount],Transactions[Custom Category],Dashboard!A43,Transactions[Month],Sel_Month),SUMIFS(Transactions[Amount],Transactions[Name],Dashboard!A43,Transactions[Month],Sel_Month)))} | E43: =IF(C43="","",IF(C43=0,0,1-((C43-D43)/C43)))
D44: {=_xlfn.IFS(A44="","",A44="Grand Total",SUM(D$4:D43),TRUE,IF(COUNTIF(Transactions[Custom Category],Dashboard!A44)>0,SUMIFS(Transactions[Amount],Transactions[Custom Category],Dashboard!A44,Transactions[Month],Sel_Month),SUMIFS(Transactions[Amount],Transactions[Name],Dashboard!A44,Transactions[Month],Sel_Month)))} | E44: =IF(C44="","",IF(C44=0,0,1-((C44-D44)/C44)))
D45: {=_xlfn.IFS(A45="","",A45="Grand Total",SUM(D$4:D44),TRUE,IF(COUNTIF(Transactions[Custom Category],Dashboard!A45)>0,SUMIFS(Transactions[Amount],Transactions[Custom Category],Dashboard!A45,Transactions[Month],Sel_Month),SUMIFS(Transactions[Amount],Transactions[Name],Dashboard!A45,Transactions[Month],Sel_Month)))} | E45: =IF(C45="","",IF(C45=0,0,1-((C45-D45)/C45)))
D46: {=_xlfn.IFS(A46="","",A46="Grand Total",SUM(D$4:D45),TRUE,IF(COUNTIF(Transactions[Custom Category],Dashboard!A46)>0,SUMIFS(Transactions[Amount],Transactions[Custom Category],Dashboard!A46,Transactions[Month],Sel_Month),SUMIFS(Transactions[Amount],Transactions[Name],Dashboard!A46,Transactions[Month],Sel_Month)))} | E46: =IF(C46="","",IF(C46=0,0,1-((C46-D46)/C46)))
D47: {=_xlfn.IFS(A47="","",A47="Grand Total",SUM(D$4:D46),TRUE,IF(COUNTIF(Transactions[Custom Category],Dashboard!A47)>0,SUMIFS(Transactions[Amount],Transactions[Custom Category],Dashboard!A47,Transactions[Month],Sel_Month),SUMIFS(Transactions[Amount],Transactions[Name],Dashboard!A47,Transactions[Month],Sel_Month)))} | E47: =IF(C47="","",IF(C47=0,0,1-((C47-D47)/C47)))
D48: {=_xlfn.IFS(A48="","",A48="Grand Total",SUM(D$4:D47),TRUE,IF(COUNTIF(Transactions[Custom Category],Dashboard!A48)>0,SUMIFS(Transactions[Amount],Transactions[Custom Category],Dashboard!A48,Transactions[Month],Sel_Month),SUMIFS(Transactions[Amount],Transactions[Name],Dashboard!A48,Transactions[Month],Sel_Month)))} | E48: =IF(C48="","",IF(C48=0,0,1-((C48-D48)/C48)))
... D434: {=_xlfn.IFS(A434="","",A434="Grand Total",SUM(D$4:D433),TRUE,IF(COUNTIF(Transactions[Custom Category],Dashboard!A434)>0,SUMIFS(Transactions[Amount],Transactions[Custom Category],Dashboard!A434,Transactions[Month],Sel_Month),SUMIFS(Transactions[Amount],Transactions[Name],Dashboard!A434,Transactions[Month],Sel_Month)))} | E434: =IF(C434="","",IF(C434=0,0,1-((C434-D434)/C434)))
D435: {=_xlfn.IFS(A435="","",A435="Grand Total",SUM(D$4:D434),TRUE,IF(COUNTIF(Transactions[Custom Category],Dashboard!A435)>0,SUMIFS(Transactions[Amount],Transactions[Custom Category],Dashboard!A435,Transactions[Month],Sel_Month),SUMIFS(Transactions[Amount],Transactions[Name],Dashboard!A435,Transactions[Month],Sel_Month)))}

Sheet Accounts
A1: Institution Name | B1: Credential ID | C1: Next Cursor | D1: Balance | E1: Mask | F1: Name | G1: Plaid Account ID | H1: Subtype | I1: Type
A2: Scotiabank | B2: 12 | C2: CAESJWdCa0xiVlBvTjVjRXZuQTFLNDF2SEI0TTg2ZW54NEM4MXltMzMaDAiZ4JuwBhCYqIXwAiIMCJngm7AGEJiohfACKgwImeCbsAYQmKiF8AI= | D2: 0.27 | E2: 386 | F2: Preferred Package | G2: prmkQjxRzEikMOjvZwjyuky9emyqeau3VyE5V | H2: checking | I2: depository
A3: Scotiabank | B3: 12 | C3: CAESJWdCa0xiVlBvTjVjRXZuQTFLNDF2SEI0TTg2ZW54NEM4MXltMzMaDAiZ4JuwBhCYqIXwAiIMCJngm7AGEJiohfACKgwImeCbsAYQmKiF8AI= | D3: 15551.34 | E3: 8692 | F3: Scotia Plan Loan | G3: XgrzK9XyN3c9JxXeELXouQ83yo8bywcdpxAZm | H3: consumer | I3: loan
A4: TD Canada Trust | B4: 13 | D4: 0 | E4: 3214 | F4: LINE OF CREDIT UNSECURED | G4: rJLZ6wO0petXPbJ0zLxECqYmVDeYwztVgPojO | H4: line of credit | I4: loan
A5: TD Canada Trust | B5: 13 | E5: 3403 | F5: MUTUAL FUND RESP - FAMILY PLAN | G5: Z0Yb9AqdaVCD4AMZy1KLuQrwvAkrXMCbL1eP1 | H5: resp | I5: investment
A6: TD Canada Trust | B6: 13 | E6: 3413 | F6: MUTUAL FUND RESP - FAMILY PLAN | G6: 54P9jkB7LKIV4NoJjx9YCOpJrPbp3wswAJrmv | H6: resp | I6: investment
A7: TD Canada Trust | B7: 13 | E7: 9351 | F7: TD EPREMIUM SAVINGS ACCOUNT | G7: jbzL89ZqpmUxBy38KJYbuV4z18r46YIew9Ek5 | H7: savings | I7: depository
A8: TD Canada Trust | B8: 13 | E8: 9W9J | F8: TFSA | G8: 4r1z0Kq56yfk65ewgDNofMZ6j1PZnBHR7wazV | H8: tfsa | I8: investment
A9: TD Canada Trust | B9: 13 | E9: 9W9K | F9: US TFSA | G9: aJYyPxvqRptKO1Dpwk4jCPdN4ModXxC75o03D | H9: tfsa | I9: investment
A10: TD Canada Trust | B10: 13 | E10: 9W9S | F10: SDRSP | G10: x13VRqpNXecvneDw93NEszypOvXyB0COQZ7pD | H10: rrsp | I10: investment
A11: TD Canada Trust | B11: 13 | E11: 9W9U | F11: US SDRSP | G11: JmgwNE95RVS9Y10npJd6CqvNk9zvm0tmvjK3w | H11: rrsp | I11: investment
A12: TD Canada Trust | B12: 13 | E12: 9W9V | F12: RESP ACCOUNT | G12: 8w3Oy0K6PvcjZd8gQV6YupxXQD0xPmHxVMokd | H12: resp | I12: investment
A13: RBC Royal Bank | B13: 14 | C13: CAESJVhwOGplemFuTnlUQk5vNkFSWG5wVUJWWm1yNm41VkN6M2dtekIaCwj2qO2wBhCIxLlLIgsI9qjtsAYQiMS5SyoLCPao7bAGEIjEuUs= | D13: -429.54 | E13: 6614 | F13: RBC Staff Banking | G13: eOMxkwaqNZH7Vznj6o6XTA4KJOvewbhnEVmgd | H13: checking | I13: depository
A14: RBC Royal Bank | B14: 14 | C14: CAESJVhwOGplemFuTnlUQk5vNkFSWG5wVUJWWm1yNm41VkN6M2dtekIaCwj2qO2wBhCIxLlLIgsI9qjtsAYQiMS5SyoLCPao7bAGEIjEuUs= | D14: 102.46 | E14: 9669 | F14: WestJet RBC World Elite Mastercard | G14: NpJvYzRnNdTaNZ0XOMOATOvYmey8M7ioaPe7Y | H14: credit card | I14: credit
A15: Scotiabank | B15: 12 | C15: CAESJWdCa0xiVlBvTjVjRXZuQTFLNDF2SEI0TTg2ZW54NEM4MXltMzMaDAiZ4JuwBhCYqIXwAiIMCJngm7AGEJiohfACKgwImeCbsAYQmKiF8AI= | D15: 0.27 | E15: 386 | F15: Preferred Package | G15: prmkQjxRzEikMOjvZwjyuky9emyqeau3VyE5V | H15: checking | I15: depository
A16: Scotiabank | B16: 12 | C16: CAESJWdCa0xiVlBvTjVjRXZuQTFLNDF2SEI0TTg2ZW54NEM4MXltMzMaDAiZ4JuwBhCYqIXwAiIMCJngm7AGEJiohfACKgwImeCbsAYQmKiF8AI= | D16: 15551.34 | E16: 8692 | F16: Scotia Plan Loan | G16: XgrzK9XyN3c9JxXeELXouQ83yo8bywcdpxAZm | H16: consumer | I16: loan
A17: TD Canada Trust | B17: 13 | D17: 0 | E17: 3214 | F17: LINE OF CREDIT UNSECURED | G17: rJLZ6wO0petXPbJ0zLxECqYmVDeYwztVgPojO | H17: line of credit | I17: loan
A18: TD Canada Trust | B18: 13 | D18: 0 | E18: 3403 | F18: MUTUAL FUND RESP - FAMILY PLAN | G18: Z0Yb9AqdaVCD4AMZy1KLuQrwvAkrXMCbL1eP1 | H18: resp | I18: investment
A19: TD Canada Trust | B19: 13 | D19: 0 | E19: 3413 | F19: MUTUAL FUND RESP - FAMILY PLAN | G19: 54P9jkB7LKIV4NoJjx9YCOpJrPbp3wswAJrmv | H19: resp | I19: investment
A20: TD Canada Trust | B20: 13 | E20: 9351 | F20: TD EPREMIUM SAVINGS ACCOUNT | G20: jbzL89ZqpmUxBy38KJYbuV4z18r46YIew9Ek5 | H20: savings | I20: depository
A21: TD Canada Trust | B21: 13 | E21: 9W9J | F21: TFSA | G21: 4r1z0Kq56yfk65ewgDNofMZ6j1PZnBHR7wazV | H21: tfsa | I21: investment
A22: TD Canada Trust | B22: 13 | E22: 9W9K | F22: US TFSA | G22: aJYyPxvqRptKO1Dpwk4jCPdN4ModXxC75o03D | H22: tfsa | I22: investment
A23: TD Canada Trust | B23: 13 | E23: 9W9S | F23: SDRSP | G23: x13VRqpNXecvneDw93NEszypOvXyB0COQZ7pD | H23: rrsp | I23: investment
A24: TD Canada Trust | B24: 13 | E24: 9W9U | F24: US SDRSP | G24: JmgwNE95RVS9Y10npJd6CqvNk9zvm0tmvjK3w | H24: rrsp | I24: investment
A25: TD Canada Trust | B25: 13 | E25: 9W9V | F25: RESP ACCOUNT | G25: 8w3Oy0K6PvcjZd8gQV6YupxXQD0xPmHxVMokd | H25: resp | I25: investment
A26: RBC Royal Bank | B26: 14 | C26: CAESJVhwOGplemFuTnlUQk5vNkFSWG5wVUJWWm1yNm41VkN6M2dtekIaCwj2qO2wBhCIxLlLIgsI9qjtsAYQiMS5SyoLCPao7bAGEIjEuUs= | D26: -429.54 | E26: 6614 | F26: RBC Staff Banking | G26: eOMxkwaqNZH7Vznj6o6XTA4KJOvewbhnEVmgd | H26: checking | I26: depository
A27: RBC Royal Bank | B27: 14 | C27: CAESJVhwOGplemFuTnlUQk5vNkFSWG5wVUJWWm1yNm41VkN6M2dtekIaCwj2qO2wBhCIxLlLIgsI9qjtsAYQiMS5SyoLCPao7bAGEIjEuUs= | D27: 102.46 | E27: 9669 | F27: WestJet RBC World Elite Mastercard | G27: NpJvYzRnNdTaNZ0XOMOATOvYmey8M7ioaPe7Y | H27: credit card | I27: credit

Sheet Transactions
A1: Account ID | B1: Action | C1: Amount | D1: Categories | E1: Date | F1: ISO Currency Code | G1: Merchant Name | H1: Name | I1: Payment Channel | J1: Pending | K1: Transaction ID | L1: Account Name | M1: Bank | N1: Operation | O1: Custom Category | P1: Datetime | Q1: Month | R1: Recent | S1: 6M AVG | T1: Month's Total | U1: Budget | V1: Sel Month
A2: eOMxkwaqNZH7Vznj6o6XTA4KJOvewbhnEVmgd | B2: added | C2: 2000 | D2: Transfer, Debit | E2: 2022-04-03, 8:00:00 p.m. | F2: CAD | H2: Online Banking transfer - 8102 | I2: other | J2: FALSE | K2: BXVyezjPrgSxXRna9M9wIa65QjPRpru3BPr6o | L2: =_xlfn.XLOOKUP(Transactions[[#This Row],[Account ID]],Accounts[Plaid Account ID],Accounts[Name],"Not Found",0) -> RBC Staff Banking | M2: =_xlfn.XLOOKUP(Transactions[[#This Row],[Account ID]],Accounts[Plaid Account ID],Accounts[Institution Name],"Not Found",0) -> RBC Royal Bank | N2: =IF(Transactions[[#This Row],[Amount]]<0,"credit","debit") -> debit | O2: {=IF( ISNUMBER(MATCH(Transactions[[#This Row],[Categories]], _xlfn._xlws.FILTER(Custom_Cat[Name], LEN(Custom_Cat[Name]) >= 3), 0)), INDEX(Custom_Cat[Custom Category], MATCH(Transactions[[#This Row],[Categories]], _xlfn._xlws.FILTER(Custom_Cat[Name], LEN(Custom_Cat[Name]) >= 3), 0)), IFERROR( INDEX( Custom_Cat[Custom Category], MATCH( 1, (ISNUMBER(SEARCH(LOWER(Custom_Cat[Name]), LOWER(Transactions[[#This Row],[Name]])))) * (LEN(Custom_Cat[Name]) >= 3) * ( (IF(LEFT(Custom_Cat[Amount],1)="<",Transactions[[#This Row],[Amount]]<VALUE(MID(Custom_Cat[Amount], 2, LEN(Custom_Cat[Amount])-1)),TRUE)) * (IF(LEFT(Custom_Cat[Amount],1)=">",Transactions[[#This Row],[Amount]]>VALUE(MID(Custom_Cat[Amount], 2, LEN(Custom_Cat[Amount])-1)),TRUE)) ), 0 ) ), Transactions[[#This Row],[Categories]] ) )} -> Transfer, Debit | P2: =DATE(LEFT(Transactions[[#This Row],[Date]],4),MID(Transactions[[#This Row],[Date]],6,2),MID(Transactions[[#This Row],[Date]],9,2))+IF(RIGHT(Transactions[[#This Row],[Date]],2)="pm",IF(MID(Transactions[[#This Row],[Date]],12,2)<12,0.5,0),IF(MID(Transactions[[#This Row],[Date]],12,2)=12,-0.5,0)) -> 44654 | Q2: =DATE(YEAR(Transactions[[#This Row],[Datetime]]),MONTH(Transactions[[#This Row],[Datetime]]),1) -> 44652 | R2: =AND(Transactions[[#This Row],[Datetime]]>=EDATE(MAX(Transactions[Datetime]),-6),Transactions[[#This Row],[Datetime]]<=TODAY()) -> FALSE | S2: =AVERAGEIFS(Transactions[Month''s Total],Transactions[Recent],TRUE,Transactions[Custom Category],Transactions[[#This Row],[Custom Category]]) -> 12758.461 | T2: =SUMIFS(Transactions[Amount],Transactions[Month],Transactions[[#This Row],[Month]],Transactions[Custom Category],Transactions[[#This Row],[Custom Category]]) -> 5295.62 | U2: =IF(COUNTIF(Budgets[Custom Category],Transactions[[#This Row],[Custom Category]])=0,Transactions[[#This Row],[6M AVG]],_xlfn.XLOOKUP(Transactions[[#This Row],[Custom Category]],Budgets[Custom Category],Budgets[Monthly],0,0)) -> 12758.461 | V2: =IF(Transactions[[#This Row],[Month]]=Sel_Month,Transactions[[#This Row],[Amount]],0) -> 0
A3: eOMxkwaqNZH7Vznj6o6XTA4KJOvewbhnEVmgd | B3: added | C3: 1444.17 | D3: Transfer, Debit | E3: 2022-04-03, 8:00:00 p.m. | F3: CAD | H3: Online Banking transfer - 0349 | I3: other | J3: FALSE | K3: 3XqR5pwB6kSDXQKBzEzJcMaqRzJov7Io13Rbp | L3: =_xlfn.XLOOKUP(Transactions[[#This Row],[Account ID]],Accounts[Plaid Account ID],Accounts[Name],"Not Found",0) -> RBC Staff Banking | M3: =_xlfn.XLOOKUP(Transactions[[#This Row],[Account ID]],Accounts[Plaid Account ID],Accounts[Institution Name],"Not Found",0) -> RBC Royal Bank | N3: =IF(Transactions[[#This Row],[Amount]]<0,"credit","debit") -> debit | O3: {=IF( ISNUMBER(MATCH(Transactions[[#This Row],[Categories]], _xlfn._xlws.FILTER(Custom_Cat[Name], LEN(Custom_Cat[Name]) >= 3), 0)), INDEX(Custom_Cat[Custom Category], MATCH(Transactions[[#This Row],[Categories]], _xlfn._xlws.FILTER(Custom_Cat[Name], LEN(Custom_Cat[Name]) >= 3), 0)), IFERROR( INDEX( Custom_Cat[Custom Category], MATCH( 1, (ISNUMBER(SEARCH(LOWER(Custom_Cat[Name]), LOWER(Transactions[[#This Row],[Name]])))) * (LEN(Custom_Cat[Name]) >= 3) * ( (IF(LEFT(Custom_Cat[Amount],1)="<",Transactions[[#This Row],[Amount]]<VALUE(MID(Custom_Cat[Amount], 2, LEN(Custom_Cat[Amount])-1)),TRUE)) * (IF(LEFT(Custom_Cat[Amount],1)=">",Transactions[[#This Row],[Amount]]>VALUE(MID(Custom_Cat[Amount], 2, LEN(Custom_Cat[Amount])-1)),TRUE)) ), 0 ) ), Transactions[[#This Row],[Categories]] ) )} -> Transfer, Debit | P3: =DATE(LEFT(Transactions[[#This Row],[Date]],4),MID(Transactions[[#This Row],[Date]],6,2),MID(Transactions[[#This Row],[Date]],9,2))+IF(RIGHT(Transactions[[#This Row],[Date]],2)="pm",IF(MID(Transactions[[#This Row],[Date]],12,2)<12,0.5,0),IF(MID(Transactions[[#This Row],[Date]],12,2)=12,-0.5,0)) -> 44654 | Q3: =DATE(YEAR(Transactions[[#This Row],[Datetime]]),MONTH(Transactions[[#This Row],[Datetime]]),1) -> 44652 | R3: =AND(Transactions[[#This Row],[Datetime]]>=EDATE(MAX(Transactions[Datetime]),-6),Transactions[[#This Row],[Datetime]]<=TODAY()) -> FALSE | S3: =AVERAGEIFS(Transactions[Month''s Total],Transactions[Recent],TRUE,Transactions[Custom Category],Transactions[[#This Row],[Custom Category]]) -> 12758.461 | T3: =SUMIFS(Transactions[Amount],Transactions[Month],Transactions[[#This Row],[Month]],Transactions[Custom Category],Transactions[[#This Row],[Custom Category]]) -> 5295.62 | U3: =IF(COUNTIF(Budgets[Custom Category],Transactions[[#This Row],[Custom Category]])=0,Transactions[[#This Row],[6M AVG]],_xlfn.XLOOKUP(Transactions[[#This Row],[Custom Category]],Budgets[Custom Category],Budgets[Monthly],0,0)) -> 12758.461 | V3: =IF(Transactions[[#This Row],[Month]]=Sel_Month,Transactions[[#This Row],[Amount]],0) -> 0
A4: eOMxkwaqNZH7Vznj6o6XTA4KJOvewbhnEVmgd | B4: added | C4: 1500 | D4: Transfer, Debit | E4: 2022-04-03, 8:00:00 p.m. | F4: CAD | H4: e-Transfer sent Manuel CIBC | I4: other | J4: FALSE | K4: yb6XYJp8zDT3z0Oj6P61uAR95LwZj7TpQev04 | L4: =_xlfn.XLOOKUP(Transactions[[#This Row],[Account ID]],Accounts[Plaid Account ID],Accounts[Name],"Not Found",0) -> RBC Staff Banking | M4: =_xlfn.XLOOKUP(Transactions[[#This Row],[Account ID]],Accounts[Plaid Account ID],Accounts[Institution Name],"Not Found",0) -> RBC Royal Bank | N4: =IF(Transactions[[#This Row],[Amount]]<0,"credit","debit") -> debit | O4: {=IF( ISNUMBER(MATCH(Transactions[[#This Row],[Categories]], _xlfn._xlws.FILTER(Custom_Cat[Name], LEN(Custom_Cat[Name]) >= 3), 0)), INDEX(Custom_Cat[Custom Category], MATCH(Transactions[[#This Row],[Categories]], _xlfn._xlws.FILTER(Custom_Cat[Name], LEN(Custom_Cat[Name]) >= 3), 0)), IFERROR( INDEX( Custom_Cat[Custom Category], MATCH( 1, (ISNUMBER(SEARCH(LOWER(Custom_Cat[Name]), LOWER(Transactions[[#This Row],[Name]])))) * (LEN(Custom_Cat[Name]) >= 3) * ( (IF(LEFT(Custom_Cat[Amount],1)="<",Transactions[[#This Row],[Amount]]<VALUE(MID(Custom_Cat[Amount], 2, LEN(Custom_Cat[Amount])-1)),TRUE)) * (IF(LEFT(Custom_Cat[Amount],1)=">",Transactions[[#This Row],[Amount]]>VALUE(MID(Custom_Cat[Amount], 2, LEN(Custom_Cat[Amount])-1)),TRUE)) ), 0 ) ), Transactions[[#This Row],[Categories]] ) )} -> Transfer,Internal | P4: =DATE(LEFT(Transactions[[#This Row],[Date]],4),MID(Transactions[[#This Row],[Date]],6,2),MID(Transactions[[#This Row],[Date]],9,2))+IF(RIGHT(Transactions[[#This Row],[Date]],2)="pm",IF(MID(Transactions[[#This Row],[Date]],12,2)<12,0.5,0),IF(MID(Transactions[[#This Row],[Date]],12,2)=12,-0.5,0)) -> 44654 | Q4: =DATE(YEAR(Transactions[[#This Row],[Datetime]]),MONTH(Transactions[[#This Row],[Datetime]]),1) -> 44652 | R4: =AND(Transactions[[#This Row],[Datetime]]>=EDATE(MAX(Transactions[Datetime]),-6),Transactions[[#This Row],[Datetime]]<=TODAY()) -> FALSE | S4: =AVERAGEIFS(Transactions[Month''s Total],Transactions[Recent],TRUE,Transactions[Custom Category],Transactions[[#This Row],[Custom Category]]) -> 14532.99 | T4: =SUMIFS(Transactions[Amount],Transactions[Month],Transactions[[#This Row],[Month]],Transactions[Custom Category],Transactions[[#This Row],[Custom Category]]) -> 8446.13 | U4: =IF(COUNTIF(Budgets[Custom Category],Transactions[[#This Row],[Custom Category]])=0,Transactions[[#This Row],[6M AVG]],_xlfn.XLOOKUP(Transactions[[#This Row],[Custom Category]],Budgets[Custom Category],Budgets[Monthly],0,0)) -> 14532.99 | V4: =IF(Transactions[[#This Row],[Month]]=Sel_Month,Transactions[[#This Row],[Amount]],0) -> 0
A5: eOMxkwaqNZH7Vznj6o6XTA4KJOvewbhnEVmgd | B5: added | C5: 1100 | D5: Transfer, Debit | E5: 2022-04-03, 8:00:00 p.m. | F5: CAD | H5: e-Transfer sent Mon Petit Univers | I5: other | J5: FALSE | K5: KYmvezN0bnso8Rk5dDdyTx4XOVejyKUE9a60r | L5: =_xlfn.XLOOKUP(Transactions[[#This Row],[Account ID]],Accounts[Plaid Account ID],Accounts[Name],"Not Found",0) -> RBC Staff Banking | M5: =_xlfn.XLOOKUP(Transactions[[#This Row],[Account ID]],Accounts[Plaid Account ID],Accounts[Institution Name],"Not Found",0) -> RBC Royal Bank | N5: =IF(Transactions[[#This Row],[Amount]]<0,"credit","debit") -> debit | O5: {=IF( ISNUMBER(MATCH(Transactions[[#This Row],[Categories]], _xlfn._xlws.FILTER(Custom_Cat[Name], LEN(Custom_Cat[Name]) >= 3), 0)), INDEX(Custom_Cat[Custom Category], MATCH(Transactions[[#This Row],[Categories]], _xlfn._xlws.FILTER(Custom_Cat[Name], LEN(Custom_Cat[Name]) >= 3), 0)), IFERROR( INDEX( Custom_Cat[Custom Category], MATCH( 1, (ISNUMBER(SEARCH(LOWER(Custom_Cat[Name]), LOWER(Transactions[[#This Row],[Name]])))) * (LEN(Custom_Cat[Name]) >= 3) * ( (IF(LEFT(Custom_Cat[Amount],1)="<",Transactions[[#This Row],[Amount]]<VALUE(MID(Custom_Cat[Amount], 2, LEN(Custom_Cat[Amount])-1)),TRUE)) * (IF(LEFT(Custom_Cat[Amount],1)=">",Transactions[[#This Row],[Amount]]>VALUE(MID(Custom_Cat[Amount], 2, LEN(Custom_Cat[Amount])-1)),TRUE)) ), 0 ) ), Transactions[[#This Row],[Categories]] ) )} -> Transfer, Debit | P5: =DATE(LEFT(Transactions[[#This Row],[Date]],4),MID(Transactions[[#This Row],[Date]],6,2),MID(Transactions[[#This Row],[Date]],9,2))+IF(RIGHT(Transactions[[#This Row],[Date]],2)="pm",IF(MID(Transactions[[#This Row],[Date]],12,2)<12,0.5,0),IF(MID(Transactions[[#This Row],[Date]],12,2)=12,-0.5,0)) -> 44654 | Q5: =DATE(YEAR(Transactions[[#This Row],[Datetime]]),MONTH(Transactions[[#This Row],[Datetime]]),1) -> 44652 | R5: =AND(Transactions[[#This Row],[Datetime]]>=EDATE(MAX(Transactions[Datetime]),-6),Transactions[[#This Row],[Datetime]]<=TODAY()) -> FALSE | S5: =AVERAGEIFS(Transactions[Month''s Total],Transactions[Recent],TRUE,Transactions[Custom Category],Transactions[[#This Row],[Custom Category]]) -> 12758.461 | T5: =SUMIFS(Transactions[Amount],Transactions[Month],Transactions[[#This Row],[Month]],Transactions[Custom Category],Transactions[[#This Row],[Custom Category]]) -> 5295.62 | U5: =IF(COUNTIF(Budgets[Custom Category],Transactions[[#This Row],[Custom Category]])=0,Transactions[[#This Row],[6M AVG]],_xlfn.XLOOKUP(Transactions[[#This Row],[Custom Category]],Budgets[Custom Category],Budgets[Monthly],0,0)) -> 12758.461 | V5: =IF(Transactions[[#This Row],[Month]]=Sel_Month,Transactions[[#This Row],[Amount]],0) -> 0
A6: eOMxkwaqNZH7Vznj6o6XTA4KJOvewbhnEVmgd | B6: added | C6: 800 | D6: Transfer, Debit | E6: 2022-04-03, 8:00:00 p.m. | F6: CAD | H6: e-Transfer sent Paula Amariles | I6: other | J6: FALSE | K6: kObx4qpAm9HOVm5g9D90iNbgweVADmHo5znM5 | L6: =_xlfn.XLOOKUP(Transactions[[#This Row],[Account ID]],Accounts[Plaid Account ID],Accounts[Name],"Not Found",0) -> RBC Staff Banking | M6: =_xlfn.XLOOKUP(Transactions[[#This Row],[Account ID]],Accounts[Plaid Account ID],Accounts[Institution Name],"Not Found",0) -> RBC Royal Bank | N6: =IF(Transactions[[#This Row],[Amount]]<0,"credit","debit") -> debit | O6: {=IF( ISNUMBER(MATCH(Transactions[[#This Row],[Categories]], _xlfn._xlws.FILTER(Custom_Cat[Name], LEN(Custom_Cat[Name]) >= 3), 0)), INDEX(Custom_Cat[Custom Category], MATCH(Transactions[[#This Row],[Categories]], _xlfn._xlws.FILTER(Custom_Cat[Name], LEN(Custom_Cat[Name]) >= 3), 0)), IFERROR( INDEX( Custom_Cat[Custom Category], MATCH( 1, (ISNUMBER(SEARCH(LOWER(Custom_Cat[Name]), LOWER(Transactions[[#This Row],[Name]])))) * (LEN(Custom_Cat[Name]) >= 3) * ( (IF(LEFT(Custom_Cat[Amount],1)="<",Transactions[[#This Row],[Amount]]<VALUE(MID(Custom_Cat[Amount], 2, LEN(Custom_Cat[Amount])-1)),TRUE)) * (IF(LEFT(Custom_Cat[Amount],1)=">",Transactions[[#This Row],[Amount]]>VALUE(MID(Custom_Cat[Amount], 2, LEN(Custom_Cat[Amount])-1)),TRUE)) ), 0 ) ), Transactions[[#This Row],[Categories]] ) )} -> Transfer,Internal | P6: =DATE(LEFT(Transactions[[#This Row],[Date]],4),MID(Transactions[[#This Row],[Date]],6,2),MID(Transactions[[#This Row],[Date]],9,2))+IF(RIGHT(Transactions[[#This Row],[Date]],2)="pm",IF(MID(Transactions[[#This Row],[Date]],12,2)<12,0.5,0),IF(MID(Transactions[[#This Row],[Date]],12,2)=12,-0.5,0)) -> 44654 | Q6: =DATE(YEAR(Transactions[[#This Row],[Datetime]]),MONTH(Transactions[[#This Row],[Datetime]]),1) -> 44652 | R6: =AND(Transactions[[#This Row],[Datetime]]>=EDATE(MAX(Transactions[Datetime]),-6),Transactions[[#This Row],[Datetime]]<=TODAY()) -> FALSE | S6: =AVERAGEIFS(Transactions[Month''s Total],Transactions[Recent],TRUE,Transactions[Custom Category],Transactions[[#This Row],[Custom Category]]) -> 14532.99 | T6: =SUMIFS(Transactions[Amount],Transactions[Month],Transactions[[#This Row],[Month]],Transactions[Custom Category],Transactions[[#This Row],[Custom Category]]) -> 8446.13 | U6: =IF(COUNTIF(Budgets[Custom Category],Transactions[[#This Row],[Custom Category]])=0,Transactions[[#This Row],[6M AVG]],_xlfn.XLOOKUP(Transactions[[#This Row],[Custom Category]],Budgets[Custom Category],Budgets[Monthly],0,0)) -> 14532.99 | V6: =IF(Transactions[[#This Row],[Month]]=Sel_Month,Transactions[[#This Row],[Amount]],0) -> 0
A7: eOMxkwaqNZH7Vznj6o6XTA4KJOvewbhnEVmgd | B7: added | C7: 359.58 | D7: Transfer, Debit | E7: 2022-04-03, 8:00:00 p.m. | F7: CAD | H7: e-Transfer sent Manuel CIBC | I7: other | J7: FALSE | K7: AXN3ez01jbS3APoek4kdu09LwN1vAaCMVrzdy | L7: =_xlfn.XLOOKUP(Transactions[[#This Row],[Account ID]],Accounts[Plaid Account ID],Accounts[Name],"Not Found",0) -> RBC Staff Banking | M7: =_xlfn.XLOOKUP(Transactions[[#This Row],[Account ID]],Accounts[Plaid Account ID],Accounts[Institution Name],"Not Found",0) -> RBC Royal Bank | N7: =IF(Transactions[[#This Row],[Amount]]<0,"credit","debit") -> debit | O7: {=IF( ISNUMBER(MATCH(Transactions[[#This Row],[Categories]], _xlfn._xlws.FILTER(Custom_Cat[Name], LEN(Custom_Cat[Name]) >= 3), 0)), INDEX(Custom_Cat[Custom Category], MATCH(Transactions[[#This Row],[Categories]], _xlfn._xlws.FILTER(Custom_Cat[Name], LEN(Custom_Cat[Name]) >= 3), 0)), IFERROR( INDEX( Custom_Cat[Custom Category], MATCH( 1, (ISNUMBER(SEARCH(LOWER(Custom_Cat[Name]), LOWER(Transactions[[#This Row],[Name]])))) * (LEN(Custom_Cat[Name]) >= 3) * ( (IF(LEFT(Custom_Cat[Amount],1)="<",Transactions[[#This Row],[Amount]]<VALUE(MID(Custom_Cat[Amount], 2, LEN(Custom_Cat[Amount])-1)),TRUE)) * (IF(LEFT(Custom_Cat[Amount],1)=">",Transactions[[#This Row],[Amount]]>VALUE(MID(Custom_Cat[Amount], 2, LEN(Custom_Cat[Amount])-1)),TRUE)) ), 0 ) ), Transactions[[#This Row],[Categories]] ) )} -> Transfer,Internal | P7: =DATE(LEFT(Transactions[[#This Row],[Date]],4),MID(Transactions[[#This Row],[Date]],6,2),MID(Transactions[[#This Row],[Date]],9,2))+IF(RIGHT(Transactions[[#This Row],[Date]],2)="pm",IF(MID(Transactions[[#This Row],[Date]],12,2)<12,0.5,0),IF(MID(Transactions[[#This Row],[Date]],12,2)=12,-0.5,0)) -> 44654 | Q7: =DATE(YEAR(Transactions[[#This Row],[Datetime]]),MONTH(Transactions[[#This Row],[Datetime]]),1) -> 44652 | R7: =AND(Transactions[[#This Row],[Datetime]]>=EDATE(MAX(Transactions[Datetime]),-6),Transactions[[#This Row],[Datetime]]<=TODAY()) -> FALSE | S7: =AVERAGEIFS(Transactions[Month''s Total],Transactions[Recent],TRUE,Transactions[Custom Category],Transactions[[#This Row],[Custom Category]]) -> 14532.99 | T7: =SUMIFS(Transactions[Amount],Transactions[Month],Transactions[[#This Row],[Month]],Transactions[Custom Category],Transactions[[#This Row],[Custom Category]]) -> 8446.13 | U7: =IF(COUNTIF(Budgets[Custom Category],Transactions[[#This Row],[Custom Category]])=0,Transactions[[#This Row],[6M AVG]],_xlfn.XLOOKUP(Transactions[[#This Row],[Custom Category]],Budgets[Custom Category],Budgets[Monthly],0,0)) -> 14532.99 | V7: =IF(Transactions[[#This Row],[Month]]=Sel_Month,Transactions[[#This Row],[Amount]],0) -> 0
A8: eOMxkwaqNZH7Vznj6o6XTA4KJOvewbhnEVmgd | B8: added | C8: -2000 | D8: Transfer, Credit | E8: 2022-04-03, 8:00:00 p.m. | F8: CAD | H8: Online transfer received - 5342 AUTOMATOS CONSULTING INC. | I8: other | J8: FALSE | K8: 0XDrJpO173S7XKVnMwM4TZO9yeN74wCApZmgq | L8: =_xlfn.XLOOKUP(Transactions[[#This Row],[Account ID]],Accounts[Plaid Account ID],Accounts[Name],"Not Found",0) -> RBC Staff Banking | M8: =_xlfn.XLOOKUP(Transactions[[#This Row],[Account ID]],Accounts[Plaid Account ID],Accounts[Institution Name],"Not Found",0) -> RBC Royal Bank | N8: =IF(Transactions[[#This Row],[Amount]]<0,"credit","debit") -> credit | O8: {=IF( ISNUMBER(MATCH(Transactions[[#This Row],[Categories]], _xlfn._xlws.FILTER(Custom_Cat[Name], LEN(Custom_Cat[Name]) >= 3), 0)), INDEX(Custom_Cat[Custom Category], MATCH(Transactions[[#This Row],[Categories]], _xlfn._xlws.FILTER(Custom_Cat[Name], LEN(Custom_Cat[Name]) >= 3), 0)), IFERROR( INDEX( Custom_Cat[Custom Category], MATCH( 1, (ISNUMBER(SEARCH(LOWER(Custom_Cat[Name]), LOWER(Transactions[[#This Row],[Name]])))) * (LEN(Custom_Cat[Name]) >= 3) * ( (IF(LEFT(Custom_Cat[Amount],1)="<",Transactions[[#This Row],[Amount]]<VALUE(MID(Custom_Cat[Amount], 2, LEN(Custom_Cat[Amount])-1)),TRUE)) * (IF(LEFT(Custom_Cat[Amount],1)=">",Transactions[[#This Row],[Amount]]>VALUE(MID(Custom_Cat[Amount], 2, LEN(Custom_Cat[Amount])-1)),TRUE)) ), 0 ) ), Transactions[[#This Row],[Categories]] ) )} -> Income,Salary | P8: =DATE(LEFT(Transactions[[#This Row],[Date]],4),MID(Transactions[[#This Row],[Date]],6,2),MID(Transactions[[#This Row],[Date]],9,2))+IF(RIGHT(Transactions[[#This Row],[Date]],2)="pm",IF(MID(Transactions[[#This Row],[Date]],12,2)<12,0.5,0),IF(MID(Transactions[[#This Row],[Date]],12,2)=12,-0.5,0)) -> 44654 | Q8: =DATE(YEAR(Transactions[[#This Row],[Datetime]]),MONTH(Transactions[[#This Row],[Datetime]]),1) -> 44652 | R8: =AND(Transactions[[#This Row],[Datetime]]>=EDATE(MAX(Transactions[Datetime]),-6),Transactions[[#This Row],[Datetime]]<=TODAY()) -> FALSE | S8: =AVERAGEIFS(Transactions[Month''s Total],Transactions[Recent],TRUE,Transactions[Custom Category],Transactions[[#This Row],[Custom Category]]) -> -18125.097 | T8: =SUMIFS(Transactions[Amount],Transactions[Month],Transactions[[#This Row],[Month]],Transactions[Custom Category],Transactions[[#This Row],[Custom Category]]) -> -11741.75 | U8: =IF(COUNTIF(Budgets[Custom Category],Transactions[[#This Row],[Custom Category]])=0,Transactions[[#This Row],[6M AVG]],_xlfn.XLOOKUP(Transactions[[#This Row],[Custom Category]],Budgets[Custom Category],Budgets[Monthly],0,0)) -> -18125.097 | V8: =IF(Transactions[[#This Row],[Month]]=Sel_Month,Transactions[[#This Row],[Amount]],0) -> 0
A9: eOMxkwaqNZH7Vznj6o6XTA4KJOvewbhnEVmgd | B9: added | C9: -2000 | D9: Transfer, Credit | E9: 2022-04-03, 8:00:00 p.m. | F9: CAD | H9: Online transfer received - 2148 AUTOMATOS CONSULTING INC. | I9: other | J9: FALSE | K9: jOoXrPpkN7HKQmxMzAzLTXvM6gnwZYHexgJ0n | L9: =_xlfn.XLOOKUP(Transactions[[#This Row],[Account ID]],Accounts[Plaid Account ID],Accounts[Name],"Not Found",0) -> RBC Staff Banking | M9: =_xlfn.XLOOKUP(Transactions[[#This Row],[Account ID]],Accounts[Plaid Account ID],Accounts[Institution Name],"Not Found",0) -> RBC Royal Bank | N9: =IF(Transactions[[#This Row],[Amount]]<0,"credit","debit") -> credit | O9: {=IF( ISNUMBER(MATCH(Transactions[[#This Row],[Categories]], _xlfn._xlws.FILTER(Custom_Cat[Name], LEN(Custom_Cat[Name]) >= 3), 0)), INDEX(Custom_Cat[Custom Category], MATCH(Transactions[[#This Row],[Categories]], _xlfn._xlws.FILTER(Custom_Cat[Name], LEN(Custom_Cat[Name]) >= 3), 0)), IFERROR( INDEX( Custom_Cat[Custom Category], MATCH( 1, (ISNUMBER(SEARCH(LOWER(Custom_Cat[Name]), LOWER(Transactions[[#This Row],[Name]])))) * (LEN(Custom_Cat[Name]) >= 3) * ( (IF(LEFT(Custom_Cat[Amount],1)="<",Transactions[[#This Row],[Amount]]<VALUE(MID(Custom_Cat[Amount], 2, LEN(Custom_Cat[Amount])-1)),TRUE)) * (IF(LEFT(Custom_Cat[Amount],1)=">",Transactions[[#This Row],[Amount]]>VALUE(MID(Custom_Cat[Amount], 2, LEN(Custom_Cat[Amount])-1)),TRUE)) ), 0 ) ), Transactions[[#This Row],[Categories]] ) )} -> Income,Salary | P9: =DATE(LEFT(Transactions[[#This Row],[Date]],4),MID(Transactions[[#This Row],[Date]],6,2),MID(Transactions[[#This Row],[Date]],9,2))+IF(RIGHT(Transactions[[#This Row],[Date]],2)="pm",IF(MID(Transactions[[#This Row],[Date]],12,2)<12,0.5,0),IF(MID(Transactions[[#This Row],[Date]],12,2)=12,-0.5,0)) -> 44654 | Q9: =DATE(YEAR(Transactions[[#This Row],[Datetime]]),MONTH(Transactions[[#This Row],[Datetime]]),1) -> 44652 | R9: =AND(Transactions[[#This Row],[Datetime]]>=EDATE(MAX(Transactions[Datetime]),-6),Transactions[[#This Row],[Datetime]]<=TODAY()) -> FALSE | S9: =AVERAGEIFS(Transactions[Month''s Total],Transactions[Recent],TRUE,Transactions[Custom Category],Transactions[[#This Row],[Custom Category]]) -> -18125.097 | T9: =SUMIFS(Transactions[Amount],Transactions[Month],Transactions[[#This Row],[Month]],Transactions[Custom Category],Transactions[[#This Row],[Custom Category]]) -> -11741.75 | U9: =IF(COUNTIF(Budgets[Custom Category],Transactions[[#This Row],[Custom Category]])=0,Transactions[[#This Row],[6M AVG]],_xlfn.XLOOKUP(Transactions[[#This Row],[Custom Category]],Budgets[Custom Category],Budgets[Monthly],0,0)) -> -18125.097 | V9: =IF(Transactions[[#This Row],[Month]]=Sel_Month,Transactions[[#This Row],[Amount]],0) -> 0
A10: eOMxkwaqNZH7Vznj6o6XTA4KJOvewbhnEVmgd | B10: added | C10: -1203.75 | D10: Transfer, Credit | E10: 2022-04-03, 8:00:00 p.m. | F10: CAD | H10: Online transfer received - 4899 AUTOMATOS CONSULTING INC. | I10: other | J10: FALSE | K10: rb4Povp8znTzYwXg9A9rIP8EwJAjozHVXqz3k | L10: =_xlfn.XLOOKUP(Transactions[[#This Row],[Account ID]],Accounts[Plaid Account ID],Accounts[Name],"Not Found",0) -> RBC Staff Banking | M10: =_xlfn.XLOOKUP(Transactions[[#This Row],[Account ID]],Accounts[Plaid Account ID],Accounts[Institution Name],"Not Found",0) -> RBC Royal Bank | N10: =IF(Transactions[[#This Row],[Amount]]<0,"credit","debit") -> credit | O10: {=IF( ISNUMBER(MATCH(Transactions[[#This Row],[Categories]], _xlfn._xlws.FILTER(Custom_Cat[Name], LEN(Custom_Cat[Name]) >= 3), 0)), INDEX(Custom_Cat[Custom Category], MATCH(Transactions[[#This Row],[Categories]], _xlfn._xlws.FILTER(Custom_Cat[Name], LEN(Custom_Cat[Name]) >= 3), 0)), IFERROR( INDEX( Custom_Cat[Custom Category], MATCH( 1, (ISNUMBER(SEARCH(LOWER(Custom_Cat[Name]), LOWER(Transactions[[#This Row],[Name]])))) * (LEN(Custom_Cat[Name]) >= 3) * ( (IF(LEFT(Custom_Cat[Amount],1)="<",Transactions[[#This Row],[Amount]]<VALUE(MID(Custom_Cat[Amount], 2, LEN(Custom_Cat[Amount])-1)),TRUE)) * (IF(LEFT(Custom_Cat[Amount],1)=">",Transactions[[#This Row],[Amount]]>VALUE(MID(Custom_Cat[Amount], 2, LEN(Custom_Cat[Amount])-1)),TRUE)) ), 0 ) ), Transactions[[#This Row],[Categories]] ) )} -> Income,Salary | P10: =DATE(LEFT(Transactions[[#This Row],[Date]],4),MID(Transactions[[#This Row],[Date]],6,2),MID(Transactions[[#This Row],[Date]],9,2))+IF(RIGHT(Transactions[[#This Row],[Date]],2)="pm",IF(MID(Transactions[[#This Row],[Date]],12,2)<12,0.5,0),IF(MID(Transactions[[#This Row],[Date]],12,2)=12,-0.5,0)) -> 44654 | Q10: =DATE(YEAR(Transactions[[#This Row],[Datetime]]),MONTH(Transactions[[#This Row],[Datetime]]),1) -> 44652 | R10: =AND(Transactions[[#This Row],[Datetime]]>=EDATE(MAX(Transactions[Datetime]),-6),Transactions[[#This Row],[Datetime]]<=TODAY()) -> FALSE | S10: =AVERAGEIFS(Transactions[Month''s Total],Transactions[Recent],TRUE,Transactions[Custom Category],Transactions[[#This Row],[Custom Category]]) -> -18125.097 | T10: =SUMIFS(Transactions[Amount],Transactions[Month],Transactions[[#This Row],[Month]],Transactions[Custom Category],Transactions[[#This Row],[Custom Category]]) -> -11741.75 | U10: =IF(COUNTIF(Budgets[Custom Category],Transactions[[#This Row],[Custom Category]])=0,Transactions[[#This Row],[6M AVG]],_xlfn.XLOOKUP(Transactions[[#This Row],[Custom Category]],Budgets[Custom Category],Budgets[Monthly],0,0)) -> -18125.097 | V10: =IF(Transactions[[#This Row],[Month]]=Sel_Month,Transactions[[#This Row],[Amount]],0) -> 0
A11: eOMxkwaqNZH7Vznj6o6XTA4KJOvewbhnEVmgd | B11: added | C11: 2000 | D11: Transfer, Debit | E11: 2022-04-13, 8:00:00 p.m. | F11: CAD | H11: e-Transfer sent Manuel CIBC | I11: other | J11: FALSE | K11: PpbjezRnN6TVNZrBQMQ0UYbVLx7r4zIo90BXz | L11: =_xlfn.XLOOKUP(Transactions[[#This Row],[Account ID]],Accounts[Plaid Account ID],Accounts[Name],"Not Found",0) -> RBC Staff Banking | M11: =_xlfn.XLOOKUP(Transactions[[#This Row],[Account ID]],Accounts[Plaid Account ID],Accounts[Institution Name],"Not Found",0) -> RBC Royal Bank | N11: =IF(Transactions[[#This Row],[Amount]]<0,"credit","debit") -> debit | O11: {=IF( ISNUMBER(MATCH(Transactions[[#This Row],[Categories]], _xlfn._xlws.FILTER(Custom_Cat[Name], LEN(Custom_Cat[Name]) >= 3), 0)), INDEX(Custom_Cat[Custom Category], MATCH(Transactions[[#This Row],[Categories]], _xlfn._xlws.FILTER(Custom_Cat[Name], LEN(Custom_Cat[Name]) >= 3), 0)), IFERROR( INDEX( Custom_Cat[Custom Category], MATCH( 1, (ISNUMBER(SEARCH(LOWER(Custom_Cat[Name]), LOWER(Transactions[[#This Row],[Name]])))) * (LEN(Custom_Cat[Name]) >= 3) * ( (IF(LEFT(Custom_Cat[Amount],1)="<",Transactions[[#This Row],[Amount]]<VALUE(MID(Custom_Cat[Amount], 2, LEN(Custom_Cat[Amount])-1)),TRUE)) * (IF(LEFT(Custom_Cat[Amount],1)=">",Transactions[[#This Row],[Amount]]>VALUE(MID(Custom_Cat[Amount], 2, LEN(Custom_Cat[Amount])-1)),TRUE)) ), 0 ) ), Transactions[[#This Row],[Categories]] ) )} -> Transfer,Internal | P11: =DATE(LEFT(Transactions[[#This Row],[Date]],4),MID(Transactions[[#This Row],[Date]],6,2),MID(Transactions[[#This Row],[Date]],9,2))+IF(RIGHT(Transactions[[#This Row],[Date]],2)="pm",IF(MID(Transactions[[#This Row],[Date]],12,2)<12,0.5,0),IF(MID(Transactions[[#This Row],[Date]],12,2)=12,-0.5,0)) -> 44664 | Q11: =DATE(YEAR(Transactions[[#This Row],[Datetime]]),MONTH(Transactions[[#This Row],[Datetime]]),1) -> 44652 | R11: =AND(Transactions[[#This Row],[Datetime]]>=EDATE(MAX(Transactions[Datetime]),-6),Transactions[[#This Row],[Datetime]]<=TODAY()) -> FALSE | S11: =AVERAGEIFS(Transactions[Month''s Total],Transactions[Recent],TRUE,Transactions[Custom Category],Transactions[[#This Row],[Custom Category]]) -> 14532.99 | T11: =SUMIFS(Transactions[Amount],Transactions[Month],Transactions[[#This Row],[Month]],Transactions[Custom Category],Transactions[[#This Row],[Custom Category]]) -> 8446.13 | U11: =IF(COUNTIF(Budgets[Custom Category],Transactions[[#This Row],[Custom Category]])=0,Transactions[[#This Row],[6M AVG]],_xlfn.XLOOKUP(Transactions[[#This Row],[Custom Category]],Budgets[Custom Category],Budgets[Monthly],0,0)) -> 14532.99 | V11: =IF(Transactions[[#This Row],[Month]]=Sel_Month,Transactions[[#This Row],[Amount]],0) -> 0
A12: eOMxkwaqNZH7Vznj6o6XTA4KJOvewbhnEVmgd | B12: added | C12: -2000 | D12: Transfer, Credit | E12: 2022-04-13, 8:00:00 p.m. | F12: CAD | H12: Online transfer received - 8625 AUTOMATOS CONSULTING INC. | I12: other | J12: FALSE | K12: qbx15Ap8zQTerAqKYXY1SVoL9aNBdRIDdm7ej | L12: =_xlfn.XLOOKUP(Transactions[[#This Row],[Account ID]],Accounts[Plaid Account ID],Accounts[Name],"Not Found",0) -> RBC Staff Banking | M12: =_xlfn.XLOOKUP(Transactions[[#This Row],[Account ID]],Accounts[Plaid Account ID],Accounts[Institution Name],"Not Found",0) -> RBC Royal Bank | N12: =IF(Transactions[[#This Row],[Amount]]<0,"credit","debit") -> credit | O12: {=IF( ISNUMBER(MATCH(Transactions[[#This Row],[Categories]], _xlfn._xlws.FILTER(Custom_Cat[Name], LEN(Custom_Cat[Name]) >= 3), 0)), INDEX(Custom_Cat[Custom Category], MATCH(Transactions[[#This Row],[Categories]], _xlfn._xlws.FILTER(Custom_Cat[Name], LEN(Custom_Cat[Name]) >= 3), 0)), IFERROR( INDEX( Custom_Cat[Custom Category], MATCH( 1, (ISNUMBER(SEARCH(LOWER(Custom_Cat[Name]), LOWER(Transactions[[#This Row],[Name]])))) * (LEN(Custom_Cat[Name]) >= 3) * ( (IF(LEFT(Custom_Cat[Amount],1)="<",Transactions[[#This Row],[Amount]]<VALUE(MID(Custom_Cat[Amount], 2, LEN(Custom_Cat[Amount])-1)),TRUE)) * (IF(LEFT(Custom_Cat[Amount],1)=">",Transactions[[#This Row],[Amount]]>VALUE(MID(Custom_Cat[Amount], 2, LEN(Custom_Cat[Amount])-1)),TRUE)) ), 0 ) ), Transactions[[#This Row],[Categories]] ) )} -> Income,Salary | P12: =DATE(LEFT(Transactions[[#This Row],[Date]],4),MID(Transactions[[#This Row],[Date]],6,2),MID(Transactions[[#This Row],[Date]],9,2))+IF(RIGHT(Transactions[[#This Row],[Date]],2)="pm",IF(MID(Transactions[[#This Row],[Date]],12,2)<12,0.5,0),IF(MID(Transactions[[#This Row],[Date]],12,2)=12,-0.5,0)) -> 44664 | Q12: =DATE(YEAR(Transactions[[#This Row],[Datetime]]),MONTH(Transactions[[#This Row],[Datetime]]),1) -> 44652 | R12: =AND(Transactions[[#This Row],[Datetime]]>=EDATE(MAX(Transactions[Datetime]),-6),Transactions[[#This Row],[Datetime]]<=TODAY()) -> FALSE | S12: =AVERAGEIFS(Transactions[Month''s Total],Transactions[Recent],TRUE,Transactions[Custom Category],Transactions[[#This Row],[Custom Category]]) -> -18125.097 | T12: =SUMIFS(Transactions[Amount],Transactions[Month],Transactions[[#This Row],[Month]],Transactions[Custom Category],Transactions[[#This Row],[Custom Category]]) -> -11741.75 | U12: =IF(COUNTIF(Budgets[Custom Category],Transactions[[#This Row],[Custom Category]])=0,Transactions[[#This Row],[6M AVG]],_xlfn.XLOOKUP(Transactions[[#This Row],[Custom Category]],Budgets[Custom Category],Budgets[Monthly],0,0)) -> -18125.097 | V12: =IF(Transactions[[#This Row],[Month]]=Sel_Month,Transactions[[#This Row],[Amount]],0) -> 0
A13: eOMxkwaqNZH7Vznj6o6XTA4KJOvewbhnEVmgd | B13: added | C13: 1749 | D13: Transfer, Debit | E13: 2022-04-21, 8:00:00 p.m. | F13: CAD | H13: e-Transfer sent Manuel CIBC | I13: other | J13: FALSE | K13: LNJEezRjgpuv83A7wmwKTZaP56woj1CZqbn9b | L13: =_xlfn.XLOOKUP(Transactions[[#This Row],[Account ID]],Accounts[Plaid Account ID],Accounts[Name],"Not Found",0) -> RBC Staff Banking | M13: =_xlfn.XLOOKUP(Transactions[[#This Row],[Account ID]],Accounts[Plaid Account ID],Accounts[Institution Name],"Not Found",0) -> RBC Royal Bank | N13: =IF(Transactions[[#This Row],[Amount]]<0,"credit","debit") -> debit | O13: {=IF( ISNUMBER(MATCH(Transactions[[#This Row],[Categories]], _xlfn._xlws.FILTER(Custom_Cat[Name], LEN(Custom_Cat[Name]) >= 3), 0)), INDEX(Custom_Cat[Custom Category], MATCH(Transactions[[#This Row],[Categories]], _xlfn._xlws.FILTER(Custom_Cat[Name], LEN(Custom_Cat[Name]) >= 3), 0)), IFERROR( INDEX( Custom_Cat[Custom Category], MATCH( 1, (ISNUMBER(SEARCH(LOWER(Custom_Cat[Name]), LOWER(Transactions[[#This Row],[Name]])))) * (LEN(Custom_Cat[Name]) >= 3) * ( (IF(LEFT(Custom_Cat[Amount],1)="<",Transactions[[#This Row],[Amount]]<VALUE(MID(Custom_Cat[Amount], 2, LEN(Custom_Cat[Amount])-1)),TRUE)) * (IF(LEFT(Custom_Cat[Amount],1)=">",Transactions[[#This Row],[Amount]]>VALUE(MID(Custom_Cat[Amount], 2, LEN(Custom_Cat[Amount])-1)),TRUE)) ), 0 ) ), Transactions[[#This Row],[Categories]] ) )} -> Transfer,Internal | P13: =DATE(LEFT(Transactions[[#This Row],[Date]],4),MID(Transactions[[#This Row],[Date]],6,2),MID(Transactions[[#This Row],[Date]],9,2))+IF(RIGHT(Transactions[[#This Row],[Date]],2)="pm",IF(MID(Transactions[[#This Row],[Date]],12,2)<12,0.5,0),IF(MID(Transactions[[#This Row],[Date]],12,2)=12,-0.5,0)) -> 44672 | Q13: =DATE(YEAR(Transactions[[#This Row],[Datetime]]),MONTH(Transactions[[#This Row],[Datetime]]),1) -> 44652 | R13: =AND(Transactions[[#This Row],[Datetime]]>=EDATE(MAX(Transactions[Datetime]),-6),Transactions[[#This Row],[Datetime]]<=TODAY()) -> FALSE | S13: =AVERAGEIFS(Transactions[Month''s Total],Transactions[Recent],TRUE,Transactions[Custom Category],Transactions[[#This Row],[Custom Category]]) -> 14532.99 | T13: =SUMIFS(Transactions[Amount],Transactions[Month],Transactions[[#This Row],[Month]],Transactions[Custom Category],Transactions[[#This Row],[Custom Category]]) -> 8446.13 | U13: =IF(COUNTIF(Budgets[Custom Category],Transactions[[#This Row],[Custom Category]])=0,Transactions[[#This Row],[6M AVG]],_xlfn.XLOOKUP(Transactions[[#This Row],[Custom Category]],Budgets[Custom Category],Budgets[Monthly],0,0)) -> 14532.99 | V13: =IF(Transactions[[#This Row],[Month]]=Sel_Month,Transactions[[#This Row],[Amount]],0) -> 0
... A202: eOMxkwaqNZH7Vznj6o6XTA4KJOvewbhnEVmgd | B202: added | C202: -3000 | D202: Transfer, Credit | E202: 2023-09-10, 8:00:00 p.m. | F202: CAD | H202: e-Transfer - Autodeposit PAULA ANDREA AMARILES RESTREPO C1Avy9FkM43a | I202: other | J202: FALSE | K202: xbwkYxX7zLT9rJvXa0a1swmEBLdAn0hOdw7Yo | L202: =_xlfn.XLOOKUP(Transactions[[#This Row],[Account ID]],Accounts[Plaid Account ID],Accounts[Name],"Not Found",0) -> RBC Staff Banking | M202: =_xlfn.XLOOKUP(Transactions[[#This Row],[Account ID]],Accounts[Plaid Account ID],Accounts[Institution Name],"Not Found",0) -> RBC Royal Bank | N202: =IF(Transactions[[#This Row],[Amount]]<0,"credit","debit") -> credit | O202: {=IF( ISNUMBER(MATCH(Transactions[[#This Row],[Categories]], _xlfn._xlws.FILTER(Custom_Cat[Name], LEN(Custom_Cat[Name]) >= 3), 0)), INDEX(Custom_Cat[Custom Category], MATCH(Transactions[[#This Row],[Categories]], _xlfn._xlws.FILTER(Custom_Cat[Name], LEN(Custom_Cat[Name]) >= 3), 0)), IFERROR( INDEX( Custom_Cat[Custom Category], MATCH( 1, (ISNUMBER(SEARCH(LOWER(Custom_Cat[Name]), LOWER(Transactions[[#This Row],[Name]])))) * (LEN(Custom_Cat[Name]) >= 3) * ( (IF(LEFT(Custom_Cat[Amount],1)="<",Transactions[[#This Row],[Amount]]<VALUE(MID(Custom_Cat[Amount], 2, LEN(Custom_Cat[Amount])-1)),TRUE)) * (IF(LEFT(Custom_Cat[Amount],1)=">",Transactions[[#This Row],[Amount]]>VALUE(MID(Custom_Cat[Amount], 2, LEN(Custom_Cat[Amount])-1)),TRUE)) ), 0 ) ), Transactions[[#This Row],[Categories]] ) )} -> Transfer,Internal | P202: =DATE(LEFT(Transactions[[#This Row],[Date]],4),MID(Transactions[[#This Row],[Date]],6,2),MID(Transactions[[#This Row],[Date]],9,2))+IF(RIGHT(Transactions[[#This Row],[Date]],2)="pm",IF(MID(Transactions[[#This Row],[Date]],12,2)<12,0.5,0),IF(MID(Transactions[[#This Row],[Date]],12,2)=12,-0.5,0)) -> 45179 | Q202: =DATE(YEAR(Transactions[[#This Row],[Datetime]]),MONTH(Transactions[[#This Row],[Datetime]]),1) -> 45170 | R202: =AND(Transactions[[#This Row],[Datetime]]>=EDATE(MAX(Transactions[Datetime]),-6),Transactions[[#This Row],[Datetime]]<=TODAY()) -> FALSE | S202: =AVERAGEIFS(Transactions[Month''s Total],Transactions[Recent],TRUE,Transactions[Custom Category],Transactions[[#This Row],[Custom Category]]) -> 14532.99 | T202: =SUMIFS(Transactions[Amount],Transactions[Month],Transactions[[#This Row],[Month]],Transactions[Custom Category],Transactions[[#This Row],[Custom Category]]) -> -9151.03 | U202: =IF(COUNTIF(Budgets[Custom Category],Transactions[[#This Row],[Custom Category]])=0,Transactions[[#This Row],[6M AVG]],_xlfn.XLOOKUP(Transactions[[#This Row],[Custom Category]],Budgets[Custom Category],Budgets[Monthly],0,0)) -> 14532.99 | V202: =IF(Transactions[[#This Row],[Month]]=Sel_Month,Transactions[[#This Row],[Amount]],0) -> 0
A203: eOMxkwaqNZH7Vznj6o6XTA4KJOvewbhnEVmgd | B203: added | C203: 74.62 | D203: Service, Utilities, Gas | E203: 2023-09-11, 8:00:00 p.m. | F203: CAD | G203: Enbridge Gas | H203: Utility Bill Pmt Enbridge Gas | I203: online | J203: FALSE | K203: 4XBJop63LASgpJk40108SNX9nADgJBHR3Pae1 | L203: =_xlfn.XLOOKUP(Transactions[[#This Row],[Account ID]],Accounts[Plaid Account ID],Accounts[Name],"Not Found",0) -> RBC Staff Banking | M203: =_xlfn.XLOOKUP(Transactions[[#This Row],[Account ID]],Accounts[Plaid Account ID],Accounts[Institution Name],"Not Found",0) -> RBC Royal Bank | N203: =IF(Transactions[[#This Row],[Amount]]<0,"credit","debit") -> debit | O203: {=IF( ISNUMBER(MATCH(Transactions[[#This Row],[Categories]], _xlfn._xlws.FILTER(Custom_Cat[Name], LEN(Custom_Cat[Name]) >= 3), 0)), INDEX(Custom_Cat[Custom Category], MATCH(Transactions[[#This Row],[Categories]], _xlfn._xlws.FILTER(Custom_Cat[Name], LEN(Custom_Cat[Name]) >= 3), 0)), IFERROR( INDEX( Custom_Cat[Custom Category], MATCH( 1, (ISNUMBER(SEARCH(LOWER(Custom_Cat[Name]), LOWER(Transactions[[#This Row],[Name]])))) * (LEN(Custom_Cat[Name]) >= 3) * ( (IF(LEFT(Custom_Cat[Amount],1)="<",Transactions[[#This Row],[Amount]]<VALUE(MID(Custom_Cat[Amount], 2, LEN(Custom_Cat[Amount])-1)),TRUE)) * (IF(LEFT(Custom_Cat[Amount],1)=">",Transactions[[#This Row],[Amount]]>VALUE(MID(Custom_Cat[Amount], 2, LEN(Custom_Cat[Amount])-1)),TRUE)) ), 0 ) ), Transactions[[#This Row],[Categories]] ) )} -> Utilities,Gas | P203: =DATE(LEFT(Transactions[[#This Row],[Date]],4),MID(Transactions[[#This Row],[Date]],6,2),MID(Transactions[[#This Row],[Date]],9,2))+IF(RIGHT(Transactions[[#This Row],[Date]],2)="pm",IF(MID(Transactions[[#This Row],[Date]],12,2)<12,0.5,0),IF(MID(Transactions[[#This Row],[Date]],12,2)=12,-0.5,0)) -> 45180 | Q203: =DATE(YEAR(Transactions[[#This Row],[Datetime]]),MONTH(Transactions[[#This Row],[Datetime]]),1) -> 45170 | R203: =AND(Transactions[[#This Row],[Datetime]]>=EDATE(MAX(Transactions[Datetime]),-6),Transactions[[#This Row],[Datetime]]<=TODAY()) -> FALSE | S203: =AVERAGEIFS(Transactions[Month''s Total],Transactions[Recent],TRUE,Transactions[Custom Category],Transactions[[#This Row],[Custom Category]]) -> 153.08333 | T203: =SUMIFS(Transactions[Amount],Transactions[Month],Transactions[[#This Row],[Month]],Transactions[Custom Category],Transactions[[#This Row],[Custom Category]]) -> 74.62 | U203: =IF(COUNTIF(Budgets[Custom Category],Transactions[[#This Row],[Custom Category]])=0,Transactions[[#This Row],[6M AVG]],_xlfn.XLOOKUP(Transactions[[#This Row],[Custom Category]],Budgets[Custom Category],Budgets[Monthly],0,0)) -> 153.08333 | V203: =IF(Transactions[[#This Row],[Month]]=Sel_Month,Transactions[[#This Row],[Amount]],0) -> 0
